
<mujoco model="humanoid_room">
  <option timestep="0.002"/>
  <worldbody>
    <geom type="plane" size="8 8 0.1" rgba="0.95 0.95 0.95 1"/>
    <geom type="box" pos="0.7 0.0 0.25" size="0.25 0.25 0.25" rgba="0.4 0.7 0.9 1"/>
    <geom type="cylinder" pos="-0.7 -0.4 0.2" size="0.2 0.2" rgba="0.9 0.6 0.4 1"/>
    <body name="torso" pos="0 0 1.1">
      <joint name="root" type="free"/>
      <geom type="capsule" fromto="0 0 0 0 0 0.3" size="0.12" rgba="0.8 0.6 0.4 1"/>
      <body name="thigh_l" pos="0.05 0 0">
        <joint name="thigh_l_joint" type="hinge" axis="1 0 0" range="-45 45"/>
        <geom type="capsule" fromto="0 0 0 0 0 -0.3" size="0.07"/>
        <body name="shank_l" pos="0 0 -0.3">
          <joint name="shank_l_joint" type="hinge" axis="1 0 0" range="-90 0"/>
          <geom type="capsule" fromto="0 0 0 0 0 -0.3" size="0.06"/>
        </body>
      </body>
      <body name="thigh_r" pos="-0.05 0 0">
        <joint name="thigh_r_joint" type="hinge" axis="1 0 0" range="-45 45"/>
        <geom type="capsule" fromto="0 0 0 0 0 -0.3" size="0.07"/>
        <body name="shank_r" pos="0 0 -0.3">
          <joint name="shank_r_joint" type="hinge" axis="1 0 0" range="-90 0"/>
          <geom type="capsule" fromto="0 0 0 0 0 -0.3" size="0.06"/>
        </body>
      </body>
    </body>
  </worldbody>
  <actuator>
    <motor joint="thigh_l_joint" gear="80"/>
    <motor joint="shank_l_joint" gear="60"/>
    <motor joint="thigh_r_joint" gear="80"/>
    <motor joint="shank_r_joint" gear="60"/>
  </actuator>
</mujoco>
